2025-07-03T20:46:29.662904Z [error    ] Another 'dev:tap-oracle-wms-full-to-target-oracle-full' pipeline is already running which started at 2025-07-03 20:40:38.068673+00:00. Wait until 2025-07-03 20:47:36.508106+00:00 when the job will be automatically cancelled if stale, or ignore this check using the '--force' option.
2025-07-03T20:46:29.663020Z [error    ] Block run completed.           block_type=ExtractLoadBlocks err=RunnerError("Another 'dev:tap-oracle-wms-full-to-target-oracle-full' pipeline is already running which started at 2025-07-03 20:40:38.068673+00:00. Wait until 2025-07-03 20:47:36.508106+00:00 when the job will be automatically cancelled if stale, or ignore this check using the '--force' option.") exit_codes={} set_number=0 success=False
2025-07-03T20:46:29.664186Z [debug    ] Need help fixing this problem? Visit http://melta.no/ for troubleshooting steps, or to
join our friendly Slack community.

Run invocation could not be completed as block failed: Another 'dev:tap-oracle-wms-full-to-target-oracle-full' pipeline is already running which started at 2025-07-03 20:40:38.068673+00:00. Wait until 2025-07-03 20:47:36.508106+00:00 when the job will be automatically cancelled if stale, or ignore this check using the '--force' option.
Traceback (most recent call last):
  File "/home/marlonsc/flext/.venv/lib/python3.13/site-packages/meltano/cli/run.py", line 218, in _run_blocks
    await blk.run()
  File "/home/marlonsc/flext/.venv/lib/python3.13/site-packages/meltano/core/block/extract_load.py", line 509, in run
    await self.run_with_job()
  File "/home/marlonsc/flext/.venv/lib/python3.13/site-packages/meltano/core/block/extract_load.py", line 545, in run_with_job
    raise RunnerError(msg)
meltano.core.runner.RunnerError: Another 'dev:tap-oracle-wms-full-to-target-oracle-full' pipeline is already running which started at 2025-07-03 20:40:38.068673+00:00. Wait until 2025-07-03 20:47:36.508106+00:00 when the job will be automatically cancelled if stale, or ignore this check using the '--force' option.

The above exception was the direct cause of the following exception:

Traceback (most recent call last):
  File "/home/marlonsc/flext/.venv/lib/python3.13/site-packages/meltano/cli/__init__.py", line 104, in _run_cli
    cli(obj={"project": None})
    ~~~^^^^^^^^^^^^^^^^^^^^^^^
  File "/home/marlonsc/flext/.venv/lib/python3.13/site-packages/click/core.py", line 1442, in __call__
    return self.main(*args, **kwargs)
           ~~~~~~~~~^^^^^^^^^^^^^^^^^
  File "/home/marlonsc/flext/.venv/lib/python3.13/site-packages/meltano/cli/cli.py", line 46, in main
    return super().main(*args, windows_expand_args=False, **kwargs)
           ~~~~~~~~~~~~^^^^^^^^^^^^^^^^^^^^^^^^^^^^^^^^^^^^^^^^^^^^
  File "/home/marlonsc/flext/.venv/lib/python3.13/site-packages/click/core.py", line 1363, in main
    rv = self.invoke(ctx)
  File "/home/marlonsc/flext/.venv/lib/python3.13/site-packages/meltano/cli/utils.py", line 582, in invoke
    super().invoke(ctx)  # type: ignore[misc]
    ~~~~~~~~~~~~~~^^^^^
  File "/home/marlonsc/flext/.venv/lib/python3.13/site-packages/click/core.py", line 1830, in invoke
    return _process_result(sub_ctx.command.invoke(sub_ctx))
                           ~~~~~~~~~~~~~~~~~~~~~~^^^^^^^^^
  File "/home/marlonsc/flext/.venv/lib/python3.13/site-packages/meltano/cli/utils.py", line 631, in invoke
    super().invoke(ctx)
    ~~~~~~~~~~~~~~^^^^^
  File "/home/marlonsc/flext/.venv/lib/python3.13/site-packages/click/core.py", line 1226, in invoke
    return ctx.invoke(self.callback, **ctx.params)
           ~~~~~~~~~~^^^^^^^^^^^^^^^^^^^^^^^^^^^^^
  File "/home/marlonsc/flext/.venv/lib/python3.13/site-packages/click/core.py", line 794, in invoke
    return callback(*args, **kwargs)
  File "/home/marlonsc/flext/.venv/lib/python3.13/site-packages/meltano/cli/params.py", line 75, in decorate
    return func(*args, **kwargs)
  File "/home/marlonsc/flext/.venv/lib/python3.13/site-packages/meltano/cli/params.py", line 165, in decorate
    func(project, *args, **kwargs)
    ~~~~^^^^^^^^^^^^^^^^^^^^^^^^^^
  File "/home/marlonsc/flext/.venv/lib/python3.13/site-packages/click/decorators.py", line 34, in new_func
    return f(get_current_context(), *args, **kwargs)
  File "/home/marlonsc/flext/.venv/lib/python3.13/site-packages/meltano/core/utils/__init__.py", line 80, in wrapper
    return asyncio.run(func(*args, **kwargs))
           ~~~~~~~~~~~^^^^^^^^^^^^^^^^^^^^^^^
  File "/usr/lib/python3.13/asyncio/runners.py", line 195, in run
    return runner.run(main)
           ~~~~~~~~~~^^^^^^
  File "/usr/lib/python3.13/asyncio/runners.py", line 118, in run
    return self._loop.run_until_complete(task)
           ~~~~~~~~~~~~~~~~~~~~~~~~~~~~~^^^^^^
  File "/usr/lib/python3.13/asyncio/base_events.py", line 719, in run_until_complete
    return future.result()
           ~~~~~~~~~~~~~^^
  File "/home/marlonsc/flext/.venv/lib/python3.13/site-packages/meltano/cli/run.py", line 186, in run
    raise err
  File "/home/marlonsc/flext/.venv/lib/python3.13/site-packages/meltano/cli/run.py", line 183, in run
    await _run_blocks(tracker, parsed_blocks, dry_run=dry_run)
  File "/home/marlonsc/flext/.venv/lib/python3.13/site-packages/meltano/cli/run.py", line 230, in _run_blocks
    raise CliError(
        f"Run invocation could not be completed as block failed: {err}",  # noqa: EM102
    ) from err
meltano.cli.utils.CliError: Run invocation could not be completed as block failed: Another 'dev:tap-oracle-wms-full-to-target-oracle-full' pipeline is already running which started at 2025-07-03 20:40:38.068673+00:00. Wait until 2025-07-03 20:47:36.508106+00:00 when the job will be automatically cancelled if stale, or ignore this check using the '--force' option.

The above exception was the direct cause of the following exception:

Traceback (most recent call last):
  File "/home/marlonsc/flext/.venv/lib/python3.13/site-packages/meltano/cli/__init__.py", line 114, in _run_cli
    raise CliError(f"{troubleshooting_message}\n{err}") from err  # noqa: EM102
    ^^^^^^^^^^^^^^^^^^^^^^^^^^^^^^^^^^^^^^^^^^^^^^^^^^^^^^^^^^^^
meltano.cli.utils.CliError: Need help fixing this problem? Visit http://melta.no/ for troubleshooting steps, or to
join our friendly Slack community.

Run invocation could not be completed as block failed: Another 'dev:tap-oracle-wms-full-to-target-oracle-full' pipeline is already running which started at 2025-07-03 20:40:38.068673+00:00. Wait until 2025-07-03 20:47:36.508106+00:00 when the job will be automatically cancelled if stale, or ignore this check using the '--force' option.
